<mujoco model="kyungwon">
    <compiler angle="degree" inertiafromgeom="true" meshdir="mesh/"/>

  	<option timestep="0.00555"/>
    <default>
        <joint armature="1" damping="1" limited="true"/>
        <geom conaffinity="1" condim="1" contype="1" margin="0.001" rgba="0.8 0.6 .4 1"/>
        <motor ctrllimited="true" ctrlrange="-1.0 1.0"/>

      <default class="body">
        <geom type="capsule" condim="1" friction="1.0 0.05 0.05" solimp=".9 .99 .003" solref=".015 1"/>
        <joint type="hinge" damping="0.1" stiffness="5" armature=".007" limited="true" solimplimit="0 .99 .01"/>
        <site size=".04" group="3"/>
        <default class="force-torque">
          <site type="box" size=".01 .01 .02" rgba="1 0 0 1" />
        </default>
        <default class="touch">
          <site type="capsule" rgba="0 0 1 .3"/>
        </default>
      </default>

    </default>

    <worldbody>
        <light cutoff="100" diffuse="1 1 1" dir="-0 0 -1.3" directional="true" exponent="1" pos="0 0 1.3" specular=".1 .1 .1"/>
        <geom condim="3" friction="1 .1 .1" name="floor" pos="0 0 -1.3" rgba="0.8 0.9 0.8 1" size="20 20 0.125" type="plane"/>
		
		<body name="Hips" pos=" 0 0 0 " childclass="body">
		  <freejoint name="Hips"/>
		  <site name="Hips" class="force-torque"/>
      <!--<geom type="box" size=" 0.075 0.15 0.12 " pos=" 0 0 0.14 " quat=" 1 0 0 0 "/>-->
			<geom name="pelvis" type="sphere" pos="0 0 0.09" size="0.07" density="2226"/>
      <!--<geom name="upper_waist" type="box" size=" 0.075 0.045 0.08 " pos=" 0 0 0.25 " quat= "1 0 0 0 "/>-->
      <geom name="upper_waist" type="sphere" pos="0 0 0.26" size="0.07" density="2226"/>
      <!--<geom name="upper_waist" type="capsule" fromto="0 0 0.13 0 0 0.30" size="0.095" density="2226"/>-->
      <site name="pelvis" class="touch" type="sphere" pos="0 0 0.9" size="0.071"/>
      <site name="upper_waist" class="touch" type="sphere" pos="0 0 0.26" size="0.071"/>

			<body name="LeftHip" pos=" -0.001963 0.082442 0.002344 ">
        <site name="LeftHip" class="force-torque"/>
				<joint name="LeftHip_x" axis=" 1 0 0 " pos="0 0 0" range="-15 60" stiffness="300" damping="30" type="hinge"/>
				<joint name="LeftHip_y" axis=" 0 1 0 " pos="0 0 0" range="-140 60" stiffness="300" damping="30" type="hinge"/>
				<joint name="LeftHip_z" axis=" 0 0 1 " pos="0 0 0" range="-20 20" stiffness="300" damping="30" type="hinge"/>
				<!--<geom type="box" size=" 0.075 0.075 0.22 " pos=" 0 0 -0.22 " quat=" 1 0 0 0 "/>-->
        <geom name="left_thigh" fromto="0 0 -0.06 0 0 -0.38" size=".06" density="1269"/>
        <site name="left_thigh" class="touch" pos="0 0 -0.22" size="0.061 0.301" zaxis="0 0 -1"/>
        <!--<geom name="test_left_thigh22" type="capsule" pos="0 0 -0.22" size="0.061 0.301" zaxis="0 0 -1" rgba="0 0 1 .3" />-->

				<body name="LeftKnee" pos=" 0 0 -0.444242 ">
          <site name="LeftKnee" class="force-torque" pos="0 0 .02"/>
					<joint name="LeftKnee" axis=" 0 1 0 " pos="0 0 0" range="0 160" stiffness="300" damping="30" type="hinge"/>
					<!--<geom type="box" size=" 0.06 0.06 0.2 " pos=" 0 0 -0.22 " quat=" 1 0 0 0 "/>-->
          <geom name="left_shin" fromto="0 0 -0.045 0 0 -0.375"  size=".052" density="1014"/>
          <site name="left_shin" class="touch" pos="0 0 -0.21" size="0.053 0.165" zaxis="0 0 -1"/>
          <!--<geom name="test_left_shin22" type="capsule" pos="0 0 -0.21" size="0.053 0.165" zaxis="0 0 -1" rgba="0 0 1 .3" />-->
					<body name="LeftAnkle" pos=" 0 0 -0.431735 ">
            <site name="LeftAnkle" class="force-torque"/>
						<joint name="LeftAnkle_x" axis=" 1 0 0 " pos="0 0 0" range="-30 30" stiffness="200" damping="20" type="hinge"/>
						<joint name="LeftAnkle_y" axis=" 0 1 0 " pos="0 0 0" range="-55 55" stiffness="200" damping="20" type="hinge"/>
						<joint name="LeftAnkle_z" axis=" 0 0 1 " pos="0 0 0" range="-40 40" stiffness="200" damping="20" type="hinge"/>
						<!--<geom type="box" size=" 0.105 0.045 0.035 " pos=" 0.04 0.01 -0.05 " quat=" 1 0 0 0 "/>-->
            <geom name="left_foot" type="box" pos="0.04 0.0 -0.05" size="0.105 0.045 0.035" density="1141"/>
            <site name="left_foot" class="touch" type="box" pos="0.04 0.0 -0.05" size="0.106 0.046 0.036"/>
            <!--<geom name="test_left_foot22" type="box" pos="0.04 0.0 -0.05" size="0.106 0.046 0.036" rgba="0 0 1 .3" />-->
					</body>
				</body>
			</body>

			<body name="RightHip" pos=" -0.001963 -0.082442 0.002344 ">
        <site name="RightHip" class="force-torque"/>
				<joint name="RightHip_x" axis=" 1 0 0 " pos="0 0 0" range="-60 15" stiffness="300" damping="30" type="hinge"/>
				<joint name="RightHip_y" axis=" 0 1 0 " pos="0 0 0" range="-140 60" stiffness="300" damping="30" type="hinge"/>
				<joint name="RightHip_z" axis=" 0 0 1 " pos="0 0 0" range="-20 20" stiffness="300" damping="30" type="hinge"/>
				<!--<geom type="box" size=" 0.075 0.075 0.22 " pos=" 0 0 -0.22 " quat=" 1 0 0 0 "/>-->
        <geom name="right_thigh" fromto="0 0 -0.06 0 0 -0.38" size="0.06" density="1269"/>
        <site name="right_thigh" class="touch" pos="0 0 -0.22" size="0.061 0.301" zaxis="0 0 -1"/>

				<body name="RightKnee" pos=" 0 0 -0.444242 ">
          <site name="RightKnee" class="force-torque" pos="0 0 0"/>
					<joint name="RightKnee" axis=" 0 1 0 " pos="0 0 0" range="0 160" stiffness="300" damping="30" type="hinge"/>
					<!--<geom type="box" size=" 0.06 0.06 0.2 " pos=" 0 0 -0.22 " quat=" 1 0 0 0 "/>-->
          <geom name="right_shin" fromto="0 0 -0.045 0 0 -0.375"  size=".052" density="1014"/>
          <site name="right_shin" class="touch" pos="0 0 -0.21" size="0.053 0.165" zaxis="0 0 -1"/>

					<body name="RightAnkle" pos=" 0 0 -0.431735 ">
            <site name="RightAnkle" class="force-torque"/>
						<joint name="RightAnkle_x" axis=" 1 0 0 " pos="0 0 0" range="-30 30" stiffness="200" damping="20" type="hinge"/>
						<joint name="RightAnkle_y" axis=" 0 1 0 " pos="0 0 0" range="-55 55" stiffness="200" damping="20" type="hinge"/>
						<joint name="RightAnkle_z" axis=" 0 0 1 " pos="0 0 0" range="-40 40" stiffness="200" damping="20" type="hinge"/>
						<!--<geom type="box" size=" 0.105 0.045 0.035 " pos=" 0.04 -0.01 -0.05 " quat=" 1 0 0 0 "/>-->
            <geom name="right_foot" type="box" pos="0.04 0.0 -0.05" size="0.105 0.045 0.035" density="1141"/>
            <site name="right_foot" class="touch" type="box" pos="0.04 0.0 -0.05" size="0.106 0.046 0.036"/>
					</body>
				</body>
			</body>

			<body name="Chest" pos=" -0.005414 -0.003774 0.297994 ">
        <light name="top" pos="0 0 2" mode="trackcom"/>
        <camera name="back" pos="-3 0 1" xyaxes="0 -1 0 1 0 2" mode="trackcom"/>
        <camera name="side" pos="0 -3 1" xyaxes="1 0 0 0 1 2" mode="trackcom"/>
				<joint name="Chest_x" axis=" 1 0 0 " pos="0 0 0" range="-60 60" stiffness="600" damping="60" type="hinge"/>
				<joint name="Chest_y" axis=" 0 1 0 " pos="0 0 0" range="-60 90" stiffness="600" damping="60" type="hinge"/>
				<joint name="Chest_z" axis=" 0 0 1 " pos="0 0 0" range="-50 50" stiffness="600" damping="60" type="hinge"/>
        <geom name="torso" type="box" size=" 0.075 0.15 0.15 " pos=" 0 0 0.13 " density="1794"/>
        <site name="torso" class="touch" type="box" pos="0 0 0.13" size="0.076 0.151 0.151 "/>
				<!--<geom name="torso" type="sphere" pos="0 0 0.15" size="0.11" density="1794"/>
        <site name="torso" class="touch" type="sphere" pos="0 0 0.15" size="0.111"/> -->

        <geom name="right_clavicle" fromto="0.007191 -0.0457775 0.2287955 0.007191 -0.13 0.2376182" size=".045" density="1100"/>
        <geom name="left_clavicle" fromto="0.007191 0.0457775 0.2287955 0.007191 0.13 0.2376182" size=".045" density="1100"/>

				<body name="LeftShoulder" pos=" 0.007191 0.198 0.245686 ">
					<joint name="LeftShoulder_x" axis=" 1 0 0 " pos="0 0 0" range="-160 90" stiffness="200" damping="20" type="hinge"/>
					<joint name="LeftShoulder_y" axis=" 0 1 0 " pos="0 0 0" range="-90 90" stiffness="200" damping="20" type="hinge"/>
					<joint name="LeftShoulder_z" axis=" 0 0 1 " pos="0 0 0" range="-160 70" stiffness="200" damping="20" type="hinge"/>
					<!--<geom type="box" size=" 0.05 0.180105 0.05 " pos=" 0 0.15 0 " quat=" 1 0 0 0 "/>-->
          <geom name="left_upper_arm" fromto="0 0.05 0 0 0.30 0" size="0.045" density="982"/>
          <site name="left_upper_arm" class="touch" pos="0 0.15 0" size="0.046 0.1" zaxis="0 0 1"/>
					<body name="LeftElbow" pos=" 0 0.338862 0 ">
						<joint name="LeftElbow" axis=" 0 0 1 " pos="0 0 0" range="-150 0" stiffness="150" damping="15" type="hinge"/>
						<!--<geom type="box" size=" 0.04 0.145464 0.04 " pos=" 0 0.15 0 " quat=" 1 0 0 0 "/>-->
            <geom name="left_lower_arm" fromto="0 0.0525 0 0 0.2575 0" size="0.04" density="1056"/>
            <site name="left_lower_arm" class="touch" pos="0 0.155 0" size="0.041 0.0685" zaxis="0 0 1"/>
					</body>
				</body>

				<body name="RightShoulder" pos=" 0.007191 -0.198 0.245686 ">
					<joint name="RightShoulder_x" axis=" 1 0 0 " pos="0 0 0" range="-90 160" stiffness="200" damping="20" type="hinge"/>
					<joint name="RightShoulder_y" axis=" 0 1 0 " pos="0 0 0" range="-90 90" stiffness="200" damping="20" type="hinge"/>
					<joint name="RightShoulder_z" axis=" 0 0 1 " pos="0 0 0" range="-70 160" stiffness="200" damping="20" type="hinge"/>
          <!--<geom type="box" size=" 0.05 0.180105 0.05 " pos=" 0 -0.15 0 " quat=" 1 0 0 0 "/>-->
					<geom name="right_upper_arm" fromto="0 -0.05 0 0 -0.30 0" size=".045" density="982"/>
          <site name="right_upper_arm" class="touch" pos="0 -0.175 0" size="0.046 0.1" zaxis="0 0 1"/>
					<body name="RightElbow" pos=" 0 -0.338862 0 ">
						<joint name="RightElbow" axis=" 0 0 1 " pos="0 0 0" range="0 160" stiffness="150" damping="15" type="hinge"/>
						<!--<geom type="box" size=" 0.04 0.145464 0.04 " pos=" 0 -0.15 0 " quat=" 1 0 0 0 "/>-->
            <geom name="right_lower_arm" fromto="0 -0.0525 0 0 -0.2575 0" size="0.04" density="1056"/>
            <site name="right_lower_arm" class="touch" pos="0 -0.155 0" size="0.041 0.0685" zaxis="0 0 1"/>
          
					</body>
				</body>
        
				<body name="Neck" pos=" 0.010085 0.00045 0.327652 ">
					<joint name="Neck_x" axis=" 1 0 0 " pos="0 0 0" range="-50 50" stiffness="50" damping="5" type="hinge"/>
					<joint name="Neck_y" axis=" 0 1 0 " pos="0 0 0" range="-40 60" stiffness="50" damping="5" type="hinge"/>
					<joint name="Neck_z" axis=" 0 0 1 " pos="0 0 0" range="-45 45" stiffness="50" damping="5" type="hinge"/>
					<geom name="head" type="box" size=" 0.065 0.065 0.085 " pos=" 0 0 0.1 " density="1081"/>
          <site name="head" class="touch" pos="0 0 0.1" type="box" size=" 0.067 0.067 0.087 "/>
          <!--<geom name="test_head" type="box" pos="0 0 0.1" size=" 0.067 0.067 0.087 " rgba="0 0 1 .3" />-->
          <!--<geom name="head" type="sphere" pos="0 0 0.175" size="0.095" density="1081"/>
          <site name="head" class="touch" pos="0 0 0.12" type="sphere" size="0.103"/>-->
          <!--<geom name="head" type="cylinder" fromto="-0.05 0 0.1 0.05 0 0.1" size="0.095" density="1081"/>-->
          <camera name="egocentric" pos=".103 0 0.12" xyaxes="0 -1 0 .1 0 1" fovy="80"/>
				</body>
			</body>
		</body>
    </worldbody>

	<actuator>
		<motor name="LeftHip_x" joint="LeftHip_x" gear="135"/>
		<motor name="LeftHip_y" joint="LeftHip_y" gear="135"/>
		<motor name="LeftHip_z" joint="LeftHip_z" gear="135"/>
		<motor name="LeftKnee" joint="LeftKnee" gear="100"/>
		<motor name="LeftAnkle_x" joint="LeftAnkle_x" gear="50.0"/>
		<motor name="LeftAnkle_y" joint="LeftAnkle_y" gear="50.0"/>
		<motor name="LeftAnkle_z" joint="LeftAnkle_z" gear="50.0"/>
		<motor name="RightHip_x" joint="RightHip_x" gear="135"/>
		<motor name="RightHip_y" joint="RightHip_y" gear="135"/>
		<motor name="RightHip_z" joint="RightHip_z" gear="135"/>
		<motor name="RightKnee" joint="RightKnee" gear="100"/>
		<motor name="RightAnkle_x" joint="RightAnkle_x" gear="50.0"/>
		<motor name="RightAnkle_y" joint="RightAnkle_y" gear="50.0"/>
		<motor name="RightAnkle_z" joint="RightAnkle_z" gear="50.0"/>
		<motor name="Chest_x" joint="Chest_x" gear="135"/>
		<motor name="Chest_y" joint="Chest_y" gear="135"/>
		<motor name="Chest_z" joint="Chest_z" gear="135"/>
		<motor name="LeftShoulder_x" joint="LeftShoulder_x" gear="70"/>
		<motor name="LeftShoulder_y" joint="LeftShoulder_y" gear="70"/>
		<motor name="LeftShoulder_z" joint="LeftShoulder_z" gear="70"/>
		<motor name="LeftElbow" joint="LeftElbow" gear="60"/>
    <motor name="RightShoulder_x" joint="RightShoulder_x" gear="70"/>
		<motor name="RightShoulder_y" joint="RightShoulder_y" gear="70"/>
		<motor name="RightShoulder_z" joint="RightShoulder_z" gear="70"/>
		<motor name="RightElbow" joint="RightElbow" gear="60"/>
		<motor name="Neck_x" joint="Neck_x" gear="20"/>
		<motor name="Neck_y" joint="Neck_y" gear="20"/>
		<motor name="Neck_z" joint="Neck_z" gear="20"/>
  </actuator>

  <sensor>
    <subtreelinvel name="pelvis_subtreelinvel" body="Hips"/>
    <accelerometer name="root_accel"    site="Hips"/>
    <velocimeter name="root_vel"        site="Hips"/>
    <gyro name="root_gyro"              site="Hips"/>

    <force name="LeftAnkle_force"        site="LeftAnkle"/>
    <force name="RightAnkle_force"       site="RightAnkle"/>
    <force name="LeftKnee_force"         site="LeftKnee"/>
    <force name="RightKnee_force"        site="RightKnee"/>
    <force name="LeftHip_force"          site="LeftHip"/>
    <force name="RightHip_force"         site="RightHip"/>

    <torque name="LeftAnkle_torque"      site="LeftAnkle"/>
    <torque name="RightAnkle_torque"     site="RightAnkle"/>
    <torque name="LeftKnee_torque"       site="LeftKnee"/>
    <torque name="RightKnee_torque"      site="RightKnee"/>
    <torque name="LeftHip_torque"        site="LeftHip"/>
    <torque name="RightHip_torque"       site="RightHip"/>

    <touch name="pelvis_touch"           site="pelvis"/>
    <touch name="upper_waist_touch"      site="upper_waist"/>
    <touch name="torso_touch"            site="torso"/>
    <touch name="head_touch"             site="head"/>
    <touch name="right_upper_arm_touch"  site="right_upper_arm"/>
    <touch name="right_lower_arm_touch"  site="right_lower_arm"/>
    <touch name="left_upper_arm_touch"   site="left_upper_arm"/>
    <touch name="left_lower_arm_touch"   site="left_lower_arm"/>
    <touch name="right_thigh_touch"      site="right_thigh"/>
    <touch name="right_shin_touch"       site="right_shin"/>
    <touch name="right_foot_touch"       site="right_foot"/>
    <touch name="left_thigh_touch"       site="left_thigh"/>
    <touch name="left_shin_touch"        site="left_shin"/>
    <touch name="left_foot_touch"        site="left_foot"/>
  </sensor>

</mujoco>
